Workbook
Name mps_database: mps_database1!$A$1:$E$284

Sheet Neutral_Tandem
A1: Before Renaming | B1: After Renaming | C1: Code 1 | D1: Code 2 | E1: Code 3 | F1: not_OSA_TTS_files
A2: Accounting Detailed Report | B2: Accounting Detailed Report | C2: 0 | D2: 0 | E2: 0 | F2: Adjustments Not Posted Report
A3: Accounting Report | B3: Accounting Report | C3: 0 | D3: 0 | E3: 0 | F3: AUR History Stats
A4: Adjustment & OCC Report | B4: Adjustment & OCC Report | C4: 12Q_ | D4: 0 | E4: 0 | F4: AUR History Stats Report
A5: Adjustment GL Trans by BAN Report | B5: Adjustment Report | C5: 12O_ | D5: 0 | E5: 0 | F5: Bill Completion Check Report
A6: Adjustment GL Trans by BAN Report - New | B6: Adjustment Report | C6: 12O_ | D6: 0 | E6: 0 | F6: Detailed BAN Error Report
A7: Adjustments GL Trans by BAN Report | B7: Adjustment Report | C7: 12O_ | D7: 0 | E7: 0 | F7: Detailed BAN Error Report - with extra research
A8: Adjustments Not Posted Report | B8: Adjustments Not Posted Report | C8: 9F_ | D8: 0 | E8: 0 | F8: Detailed CLLI Error Report
A9: Aged Trial Balance for Export | B9: Aged Trial Balance for Export Report | C9: 0 | D9: 0 | E9: 0 | F9: Detailed CLLI Error Report - with extra research
A10: Aged Trial Balance for Export - New | B10: Aged Trial Balance for Export Report | C10: 0 | D10: 0 | E10: 0 | F10: Duplicate File Processing Report
A11: Aged Trial Balance_for export | B11: Aged Trial Balance for Export Report | C11: 0 | D11: 0 | E11: 0 | F11: Exception Analysis Report
A12: Aged trial Balance | B12: Aged trial Balance Report | C12: 0 | D12: 0 | E12: 0 | F12: Factor Change Audit Report
A13: Aged Trial Balance - New | B13: Aged trial Balance Report | C13: 0 | D13: 0 | E13: 0 | F13: Factor Check Report with PVU
A14: AUR History Stats | B14: AUR History Stats Report | C14: 4A_ | D14: 0 | E14: 0 | F14: Factor Compare Report
A15: AUR History Stats Report | B15: AUR History Stats Report | C15: 4A_ | D15: 0 | E15: 0 | F15: Factor Matrix Report
A16: BAN List with Active Status and LPC Option | B16: BAN List with Active Status and LPC Option | C16: 0 | D16: 0 | E16: 0 | F16: SOC Change Audit Report
A17: Bill By Period Report | B17: Bill By Period Report | C17: 0 | D17: 0 | E17: 0 | F17: Usage Balancing - Company Totals with Full Detail
A18: Bill Completion Check Report | B18: Bill Completion Check Report | C18: 12A_ | D18: 0 | E18: 0 | F18: Usage Balancing - Company, Ban Totals
A19: Billed by Period | B19: Bill By Period Report | C19: 0 | D19: 0 | E19: 0 | F19: Usage Verify by Size Report
A20: Billed by Period Report | B20: Bill By Period Report | C20: 0 | D20: 0 | E20: 0 | F20: MOU Entries Error Report
A21: Billed by Period Report - New | B21: Bill By Period Report | C21: 0 | D21: 0 | E21: 0
A22: Billed Msg MOU Rev by BAN by EMR Jurisdiction | B22: Message MOU Revenue by BAN Report | C22: 0 | D22: 0 | E22: 0
A23: Billed Msg MOU Rev by CLLI by EMR Jurisdiction | B23: Message MOU Revenue by CLLI Report | C23: 0 | D23: 0 | E23: 0
A24: CLNT ly_invoice_balances_by_jur_cic | B24: Invoice Balance Report | C24: 0 | D24: 0 | E24: 0
A25: CLNT nt_ckt_billed_live_disco_v2 | B25: Facility Circuit Charges Billed Disconnected | C25: 0 | D25: 0 | E25: 0
A26: Count of Invoices not zero Range | B26: Number Of Invoices | C26: 21B_ | D26: 0 | E26: 0
A27: Count Of Invoices not zero Range | B27: Number Of Invoices | C27: 21B_ | D27: 0 | E27: 0
A28: count_of_invoices_not_zero_range | B28: Number Of Invoices | C28: 21B_ | D28: 0 | E28: 0
A29: Deletions Under 5 Report | B29: Deletions Under 5 Report | C29: 0 | D29: 0 | E29: 0
A30: Deletions Under Report | B30: Deletions Under Report | C30: 0 | D30: 0 | E30: 0
A31: Detailed BAN Error Report | B31: Detailed BAN Error Report | C31: 4F_ | D31: 0 | E31: 0
A32: Detailed BAN Error Report - with extra research | B32: Detailed BAN Error Report | C32: 4F_ | D32: 0 | E32: 0
A33: Detailed CLLI Error Report | B33: Detailed CLLI Error Report | C33: 4H_ | D33: 0 | E33: 0
A34: Detailed CLLI Error Report - with extra research | B34: Detailed CLLI Error Report | C34: 4H_ | D34: 0 | E34: 0
A35: Duplicate File Processing Report | B35: Duplicate File Processing Report | C35: 5A_ | D35: 0 | E35: 0
A36: Exception Analysis Report | B36: Exception Analysis Report | C36: 4K_ | D36: 0 | E36: 0
A37: FA BAN Trending Report | B37: Facility BANS Trending Report | C37: 0 | D37: 0 | E37: 0
A38: FA Charges Summary | B38: FA Charges Summary | C38: 0 | D38: 0 | E38: 0
A39: FA Circuit Charges by CIC by CLLI | B39: FA Circuit Charges by CIC by CLLI | C39: 0 | D39: 0 | E39: 0
A40: Facility BANS Trending Report | B40: Facility BANS Trending Report | C40: 12B_ | D40: 12D_ | E40: 12N_
...

Sheet American_Broadband
A1: Before Renaming | B1: After Renaming | C1: Code 1 | D1: Code 2 | E1: Code 3
A2: Accounting Detailed Report | B2: Accounting Detailed Report | C2: 0 | D2: 0 | E2: 0
A3: Accounting Report | B3: Accounting Report | C3: 0 | D3: 0 | E3: 0
A4: Adjustment & OCC Report | B4: Adjustment & OCC Report | C4: 12Q_ | D4: 0 | E4: 0
A5: Adjustment GL Trans by BAN Report | B5: Adjustment Report | C5: 12O_ | D5: 0 | E5: 0
A6: Adjustment GL Trans by BAN Report - New | B6: Adjustment Report | C6: 12O_ | D6: 0 | E6: 0
A7: Adjustments GL Trans by BAN Report | B7: Adjustment Report | C7: 12O_ | D7: 0 | E7: 0
A8: Adjustments Not Posted Report | B8: Adjustments Not Posted Report | C8: 9F_ | D8: 0 | E8: 0
A9: Aged Trial Balance for Export | B9: Aged Trial Balance for Export Report | C9: 0 | D9: 0 | E9: 0
A10: Aged Trial Balance for Export - New | B10: Aged Trial Balance for Export Report | C10: 0 | D10: 0 | E10: 0
A11: Aged Trial Balance_for export | B11: Aged Trial Balance for Export Report | C11: 0 | D11: 0 | E11: 0
A12: Aged trial Balance | B12: Aged trial Balance Report | C12: 0 | D12: 0 | E12: 0
A13: Aged Trial Balance - New | B13: Aged trial Balance Report | C13: 0 | D13: 0 | E13: 0
A14: AUR History Stats | B14: AUR History Stats Report | C14: 4A_ | D14: 0 | E14: 0
A15: AUR History Stats Report | B15: AUR History Stats Report | C15: 4A_ | D15: 0 | E15: 0
A16: BAN List with Active Status and LPC Option | B16: BAN List with Active Status and LPC Option | C16: 0 | D16: 0 | E16: 0
A17: Bill By Period Report | B17: Bill By Period Report | C17: 0 | D17: 0 | E17: 0
A18: Bill Completion Check Report | B18: Bill Completion Check Report | C18: 12A_ | D18: 0 | E18: 0
A19: Billed by Period | B19: Bill By Period Report | C19: 0 | D19: 0 | E19: 0
A20: Billed by Period Report | B20: Bill By Period Report | C20: 0 | D20: 0 | E20: 0
A21: Billed by Period Report - New | B21: Bill By Period Report | C21: 0 | D21: 0 | E21: 0
A22: Billed Msg MOU Rev by BAN by EMR Jurisdiction | B22: Message MOU Revenue by BAN Report | C22: 0 | D22: 0 | E22: 0
A23: Billed Msg MOU Rev by CLLI by EMR Jurisdiction | B23: Message MOU Revenue by CLLI Report | C23: 0 | D23: 0 | E23: 0
A24: CLNT ly_invoice_balances_by_jur_cic | B24: Invoice Balance Report | C24: 0 | D24: 0 | E24: 0
A25: CLNT nt_ckt_billed_live_disco_v2 | B25: Facility Circuit Charges Billed Disconnected | C25: 0 | D25: 0 | E25: 0
A26: Count of Invoices not zero Range | B26: Number Of Invoices | C26: 21B_ | D26: 0 | E26: 0
A27: Count Of Invoices not zero Range | B27: Number Of Invoices | C27: 21B_ | D27: 0 | E27: 0
A28: count_of_invoices_not_zero_range | B28: Number Of Invoices | C28: 21B_ | D28: 0 | E28: 0
A29: Deletions Under 5 Report | B29: Deletions Under 5 Report | C29: 0 | D29: 0 | E29: 0
A30: Deletions Under Report | B30: Deletions Under Report | C30: 0 | D30: 0 | E30: 0
A31: Detailed BAN Error Report | B31: Detailed BAN Error Report | C31: 4F_ | D31: 0 | E31: 0
A32: Detailed BAN Error Report - with extra research | B32: Detailed BAN Error Report | C32: 4F_ | D32: 0 | E32: 0
A33: Detailed CLLI Error Report | B33: Detailed CLLI Error Report | C33: 4H_ | D33: 0 | E33: 0
A34: Detailed CLLI Error Report - with extra research | B34: Detailed CLLI Error Report | C34: 4H_ | D34: 0 | E34: 0
A35: Duplicate File Processing Report | B35: Duplicate File Processing Report | C35: 5A_ | D35: 0 | E35: 0
A36: Exception Analysis Report | B36: Exception Analysis Report | C36: 4K_ | D36: 0 | E36: 0
A37: FA BAN Trending Report | B37: Facility BANS Trending Report | C37: 0 | D37: 0 | E37: 0
A38: FA Charges Summary | B38: FA Charges Summary | C38: 0 | D38: 0 | E38: 0
A39: FA Circuit Charges by CIC by CLLI | B39: FA Circuit Charges by CIC by CLLI | C39: 0 | D39: 0 | E39: 0
A40: Facility BANS Trending Report | B40: Facility BANS Trending Report | C40: 12B_ | D40: 12D_ | E40: 12N_
...

Sheet Specific Names Main
A1: Before Renaming | B1: After Renaming | C1: Code 1 | D1: Code 2 | E1: Code 3
A2: Accounting Detailed Report | B2: Accounting Detailed Report | C2: 0 | D2: 0 | E2: 0
A3: Accounting Report | B3: Accounting Report | C3: 0 | D3: 0 | E3: 0
A4: Adjustment & OCC Report | B4: Adjustment & OCC Report | C4: 12Q_ | D4: 0 | E4: 0
A5: Adjustment GL Trans by BAN Report | B5: Adjustment Report | C5: 12O_ | D5: 0 | E5: 0
A6: Adjustment GL Trans by BAN Report - New | B6: Adjustment Report | C6: 12O_ | D6: 0 | E6: 0
A7: Adjustments GL Trans by BAN Report | B7: Adjustment Report | C7: 12O_ | D7: 0 | E7: 0
A8: Adjustments Not Posted Report | B8: Adjustments Not Posted Report | C8: 9F_ | D8: 0 | E8: 0
A9: Aged Trial Balance for Export | B9: Aged Trial Balance for Export Report | C9: 0 | D9: 0 | E9: 0
A10: Aged Trial Balance for Export - New | B10: Aged Trial Balance for Export Report | C10: 0 | D10: 0 | E10: 0
A11: Aged Trial Balance_for export | B11: Aged Trial Balance for Export Report | C11: 0 | D11: 0 | E11: 0
A12: Aged trial Balance | B12: Aged trial Balance Report | C12: 0 | D12: 0 | E12: 0
A13: Aged Trial Balance - New | B13: Aged trial Balance Report | C13: 0 | D13: 0 | E13: 0
A14: AUR History Stats | B14: AUR History Stats Report | C14: 4A_ | D14: 0 | E14: 0
A15: AUR History Stats Report | B15: AUR History Stats Report | C15: 4A_ | D15: 0 | E15: 0
A16: BAN List with Active Status and LPC Option | B16: BAN List with Active Status and LPC Option | C16: 0 | D16: 0 | E16: 0
A17: Bill By Period Report | B17: Bill By Period Report | C17: 0 | D17: 0 | E17: 0
A18: Bill Completion Check Report | B18: Bill Completion Check Report | C18: 12A_ | D18: 0 | E18: 0
A19: Billed by Period | B19: Bill By Period Report | C19: 0 | D19: 0 | E19: 0
A20: Billed by Period Report | B20: Bill By Period Report | C20: 0 | D20: 0 | E20: 0
A21: Billed by Period Report - New | B21: Bill By Period Report | C21: 0 | D21: 0 | E21: 0
A22: Billed Msg MOU Rev by BAN by EMR Jurisdiction | B22: Message MOU Revenue by BAN Report | C22: 0 | D22: 0 | E22: 0
A23: Billed Msg MOU Rev by CLLI by EMR Jurisdiction | B23: Message MOU Revenue by CLLI Report | C23: 0 | D23: 0 | E23: 0
A24: CLNT ly_invoice_balances_by_jur_cic | B24: Invoice Balance Report | C24: 0 | D24: 0 | E24: 0
A25: CLNT nt_ckt_billed_live_disco_v2 | B25: Facility Circuit Charges Billed Disconnected | C25: 0 | D25: 0 | E25: 0
A26: Count of Invoices not zero Range | B26: Number Of Invoices | C26: 21B_ | D26: 0 | E26: 0
A27: Count Of Invoices not zero Range | B27: Number Of Invoices | C27: 21B_ | D27: 0 | E27: 0
A28: count_of_invoices_not_zero_range | B28: Number Of Invoices | C28: 21B_ | D28: 0 | E28: 0
A29: Deletions Under 5 Report | B29: Deletions Under 5 Report | C29: 0 | D29: 0 | E29: 0
A30: Deletions Under Report | B30: Deletions Under Report | C30: 0 | D30: 0 | E30: 0
A31: Detailed BAN Error Report | B31: Detailed BAN Error Report | C31: 4F_ | D31: 0 | E31: 0
A32: Detailed BAN Error Report - with extra research | B32: Detailed BAN Error Report | C32: 4F_ | D32: 0 | E32: 0
A33: Detailed CLLI Error Report | B33: Detailed CLLI Error Report | C33: 4H_ | D33: 0 | E33: 0
A34: Detailed CLLI Error Report - with extra research | B34: Detailed CLLI Error Report | C34: 4H_ | D34: 0 | E34: 0
A35: Duplicate File Processing Report | B35: Duplicate File Processing Report | C35: 5A_ | D35: 0 | E35: 0
A36: Exception Analysis Report | B36: Exception Analysis Report | C36: 4K_ | D36: 0 | E36: 0
A37: FA BAN Trending Report | B37: Facility BANS Trending Report | C37: 0 | D37: 0 | E37: 0
A38: FA Charges Summary | B38: FA Charges Summary | C38: 0 | D38: 0 | E38: 0
A39: FA Circuit Charges by CIC by CLLI | B39: FA Circuit Charges by CIC by CLLI | C39: 0 | D39: 0 | E39: 0
A40: Facility BANS Trending Report | B40: Facility BANS Trending Report | C40: 12B_ | D40: 12D_ | E40: 12N_
...

Sheet MTA
A1: Before Renaming | B1: After Renaming | C1: Code 1 | D1: Code 2 | E1: Code 3
A2: Accounting Detailed Report | B2: Accounting Detailed Report | C2: 0 | D2: 0 | E2: 0
A3: Accounting Report | B3: Accounting Report | C3: 0 | D3: 0 | E3: 0
A4: Adjustment & OCC Report | B4: Adjustment & OCC Report | C4: 12Q_ | D4: 0 | E4: 0
A5: Adjustment GL Trans by BAN Report | B5: Adjustment Report | C5: 12O_ | D5: 0 | E5: 0
A6: Adjustment GL Trans by BAN Report - New | B6: Adjustment Report | C6: 12O_ | D6: 0 | E6: 0
A7: Adjustments GL Trans by BAN Report | B7: Adjustment Report | C7: 12O_ | D7: 0 | E7: 0
A8: Adjustments Not Posted Report | B8: Adjustments Not Posted Report | C8: 9F_ | D8: 0 | E8: 0
A9: Aged Trial Balance for Export | B9: Aged Trial Balance for Export Report | C9: 0 | D9: 0 | E9: 0
A10: Aged Trial Balance for Export - New | B10: Aged Trial Balance for Export Report | C10: 0 | D10: 0 | E10: 0
A11: Aged Trial Balance_for export | B11: Aged Trial Balance for Export Report | C11: 0 | D11: 0 | E11: 0
A12: Aged trial Balance | B12: Aged trial Balance Report | C12: 0 | D12: 0 | E12: 0
A13: Aged Trial Balance - New | B13: Aged trial Balance Report | C13: 0 | D13: 0 | E13: 0
A14: AUR History Stats | B14: AUR History Stats Report | C14: 4A_ | D14: 0 | E14: 0
A15: AUR History Stats Report | B15: AUR History Stats Report | C15: 4A_ | D15: 0 | E15: 0
A16: BAN List with Active Status and LPC Option | B16: BAN List with Active Status and LPC Option | C16: 0 | D16: 0 | E16: 0
A17: Bill By Period Report | B17: Bill By Period Report | C17: 0 | D17: 0 | E17: 0
A18: Bill Completion Check Report | B18: Bill Completion Check Report | C18: 12A_ | D18: 0 | E18: 0
A19: Billed by Period | B19: Bill By Period Report | C19: 0 | D19: 0 | E19: 0
A20: Billed by Period Report | B20: Bill By Period Report | C20: 0 | D20: 0 | E20: 0
A21: Billed by Period Report - New | B21: Bill By Period Report | C21: 0 | D21: 0 | E21: 0
A22: Billed Msg MOU Rev by BAN by EMR Jurisdiction | B22: Message MOU Revenue by BAN Report | C22: 0 | D22: 0 | E22: 0
A23: Billed Msg MOU Rev by CLLI by EMR Jurisdiction | B23: Message MOU Revenue by CLLI Report | C23: 0 | D23: 0 | E23: 0
A24: CLNT ly_invoice_balances_by_jur_cic | B24: Invoice Balance Report | C24: 0 | D24: 0 | E24: 0
A25: CLNT nt_ckt_billed_live_disco_v2 | B25: Facility Circuit Charges Billed Disconnected | C25: 0 | D25: 0 | E25: 0
A26: Count of Invoices not zero Range | B26: Number Of Invoices | C26: 21B_ | D26: 0 | E26: 0
A27: Count Of Invoices not zero Range | B27: Number Of Invoices | C27: 21B_ | D27: 0 | E27: 0
A28: count_of_invoices_not_zero_range | B28: Number Of Invoices | C28: 21B_ | D28: 0 | E28: 0
A29: Deletions Under 5 Report | B29: Deletions Under 5 Report | C29: 0 | D29: 0 | E29: 0
A30: Deletions Under Report | B30: Deletions Under Report | C30: 0 | D30: 0 | E30: 0
A31: Detailed BAN Error Report | B31: Detailed BAN Error Report | C31: 4F_ | D31: 0 | E31: 0
A32: Detailed BAN Error Report - with extra research | B32: Detailed BAN Error Report | C32: 4F_ | D32: 0 | E32: 0
A33: Detailed CLLI Error Report | B33: Detailed CLLI Error Report | C33: 4H_ | D33: 0 | E33: 0
A34: Detailed CLLI Error Report - with extra research | B34: Detailed CLLI Error Report | C34: 4H_ | D34: 0 | E34: 0
A35: Duplicate File Processing Report | B35: Duplicate File Processing Report | C35: 5A_ | D35: 0 | E35: 0
A36: Exception Analysis Report | B36: Exception Analysis Report | C36: 4K_ | D36: 0 | E36: 0
A37: FA BAN Trending Report | B37: Facility BANS Trending Report | C37: 0 | D37: 0 | E37: 0
A38: FA Charges Summary | B38: FA Charges Summary | C38: 0 | D38: 0 | E38: 0
A39: FA Circuit Charges by CIC by CLLI | B39: FA Circuit Charges by CIC by CLLI | C39: 0 | D39: 0 | E39: 0
A40: Facility BANS Trending Report | B40: Facility BANS Trending Report | C40: 12B_ | D40: 12D_ | E40: 12N_
...

Sheet ONVOY
A1: Before Renaming | B1: After Renaming | C1: Code 1 | D1: Code 2 | E1: Code 3
A2: Accounting Detailed Report | B2: Accounting Detailed Report | C2: 0 | D2: 0 | E2: 0
A3: Accounting Report | B3: Accounting Report | C3: 0 | D3: 0 | E3: 0
A4: Adjustment & OCC Report | B4: Adjustment & OCC Report | C4: 12Q_ | D4: 0 | E4: 0
A5: Adjustment GL Trans by BAN Report | B5: Adjustment Report | C5: 12O_ | D5: 0 | E5: 0
A6: Adjustment GL Trans by BAN Report - New | B6: Adjustment Report | C6: 12O_ | D6: 0 | E6: 0
A7: Adjustments GL Trans by BAN Report | B7: Adjustment Report | C7: 12O_ | D7: 0 | E7: 0
A8: Adjustments Not Posted Report | B8: Adjustments Not Posted Report | C8: 9F_ | D8: 0 | E8: 0
A9: Aged Trial Balance for Export | B9: Aged Trial Balance for Export Report | C9: 0 | D9: 0 | E9: 0
A10: Aged Trial Balance for Export - New | B10: Aged Trial Balance for Export Report | C10: 0 | D10: 0 | E10: 0
A11: Aged Trial Balance_for export | B11: Aged Trial Balance for Export Report | C11: 13B_ | D11: 0 | E11: 0
A12: Aged trial Balance | B12: Aged trial Balance Report | C12: 13B_ | D12: 0 | E12: 0
A13: Aged Trial Balance - New | B13: Aged trial Balance Report | C13: 13B_ | D13: 0 | E13: 0
A14: AUR History Stats | B14: AUR History Stats Report | C14: 4A_ | D14: 0 | E14: 0
A15: AUR History Stats Report | B15: AUR History Stats Report | C15: 4A_ | D15: 0 | E15: 0
A16: BAN List with Active Status and LPC Option | B16: BAN List with Active Status and LPC Option | C16: 0 | D16: 0 | E16: 0
A17: Bill By Period Report | B17: Bill By Period Report | C17: 0 | D17: 0 | E17: 0
A18: Bill Completion Check Report | B18: Bill Completion Check Report | C18: 12A_ | D18: 0 | E18: 0
A19: Billed by Period | B19: Bill By Period Report | C19: 0 | D19: 0 | E19: 0
A20: Billed by Period Report | B20: Bill By Period Report | C20: 0 | D20: 0 | E20: 0
A21: Billed by Period Report - New | B21: Bill By Period Report | C21: 0 | D21: 0 | E21: 0
A22: Billed Msg MOU Rev by BAN by EMR Jurisdiction | B22: Message MOU Revenue by BAN Report | C22: 13C_ | D22: 0 | E22: 0
A23: Billed Msg MOU Rev by CLLI by EMR Jurisdiction | B23: Message MOU Revenue by CLLI Report | C23: 0 | D23: 0 | E23: 0
A24: CLNT ly_invoice_balances_by_jur_cic | B24: Invoice Balance Report | C24: 0 | D24: 0 | E24: 0
A25: CLNT nt_ckt_billed_live_disco_v2 | B25: Facility Circuit Charges Billed Disconnected | C25: 0 | D25: 0 | E25: 0
A26: Count of Invoices not zero Range | B26: Number Of Invoices | C26: 21B_ | D26: 0 | E26: 0
A27: Count Of Invoices not zero Range | B27: Number Of Invoices | C27: 21B_ | D27: 0 | E27: 0
A28: count_of_invoices_not_zero_range | B28: Number Of Invoices | C28: 21B_ | D28: 0 | E28: 0
A29: Deletions Under 5 Report | B29: Deletions Under 5 Report | C29: 0 | D29: 0 | E29: 0
A30: Deletions Under Report | B30: Deletions Under Report | C30: 0 | D30: 0 | E30: 0
A31: Detailed BAN Error Report | B31: Detailed BAN Error Report | C31: 4F_ | D31: 0 | E31: 0
A32: Detailed BAN Error Report - with extra research | B32: Detailed BAN Error Report | C32: 4F_ | D32: 0 | E32: 0
A33: Detailed CLLI Error Report | B33: Detailed CLLI Error Report | C33: 4H_ | D33: 0 | E33: 0
A34: Detailed CLLI Error Report - with extra research | B34: Detailed CLLI Error Report | C34: 4H_ | D34: 0 | E34: 0
A35: Duplicate File Processing Report | B35: Duplicate File Processing Report | C35: 5A_ | D35: 0 | E35: 0
A36: Exception Analysis Report | B36: Exception Analysis Report | C36: 4K_ | D36: 0 | E36: 0
A37: FA BAN Trending Report | B37: Facility BANS Trending Report | C37: 0 | D37: 0 | E37: 0
A38: FA Charges Summary | B38: FA Charges Summary | C38: 0 | D38: 0 | E38: 0
A39: FA Circuit Charges by CIC by CLLI | B39: FA Circuit Charges by CIC by CLLI | C39: 0 | D39: 0 | E39: 0
A40: Facility BANS Trending Report | B40: Facility BANS Trending Report | C40: 12B_ | D40: 12D_ | E40: 12N_
...

Sheet Peerless_Network
A1: Before Renaming | B1: After Renaming | C1: Code 1 | D1: Code 2 | E1: Code 3
A2: Accounting Detailed Report | B2: Accounting Detailed Report | C2: 0 | D2: 0 | E2: 0
A3: Accounting Report | B3: Accounting Report | C3: 0 | D3: 0 | E3: 0
A4: Adjustment & OCC Report | B4: Adjustment & OCC Report | C4: 12Q_ | D4: 0 | E4: 0
A5: Adjustment GL Trans by BAN Report | B5: Adjustment Report | C5: 12O_ | D5: 0 | E5: 0
A6: Adjustment GL Trans by BAN Report - New | B6: Adjustment Report | C6: 12O_ | D6: 0 | E6: 0
A7: Adjustments GL Trans by BAN Report | B7: Adjustment Report | C7: 12O_ | D7: 0 | E7: 0
A8: Adjustments Not Posted Report | B8: Adjustments Not Posted Report | C8: 9F_ | D8: 0 | E8: 0
A9: Aged Trial Balance for Export | B9: Aged Trial Balance for Export Report | C9: 0 | D9: 0 | E9: 0
A10: Aged Trial Balance for Export - New | B10: Aged Trial Balance for Export Report | C10: 0 | D10: 0 | E10: 0
A11: Aged Trial Balance_for export | B11: Aged Trial Balance for Export Report | C11: 0 | D11: 0 | E11: 0
A12: Aged trial Balance | B12: Aged trial Balance Report | C12: 0 | D12: 0 | E12: 0
A13: Aged Trial Balance - New | B13: Aged trial Balance Report | C13: 0 | D13: 0 | E13: 0
A14: AUR History Stats | B14: AUR History Stats Report | C14: 4A_ | D14: 0 | E14: 0
A15: AUR History Stats Report | B15: AUR History Stats Report | C15: 4A_ | D15: 0 | E15: 0
A16: BAN List with Active Status and LPC Option | B16: BAN List with Active Status and LPC Option | C16: 0 | D16: 0 | E16: 0
A17: Bill By Period Report | B17: Bill By Period Report | C17: 0 | D17: 0 | E17: 0
A18: Bill Completion Check Report | B18: Bill Completion Check Report | C18: 12A_ | D18: 0 | E18: 0
A19: Billed by Period | B19: Bill By Period Report | C19: 0 | D19: 0 | E19: 0
A20: Billed by Period Report | B20: Bill By Period Report | C20: 0 | D20: 0 | E20: 0
A21: Billed by Period Report - New | B21: Bill By Period Report | C21: 0 | D21: 0 | E21: 0
A22: Billed Msg MOU Rev by BAN by EMR Jurisdiction | B22: Message MOU Revenue by BAN Report | C22: 0 | D22: 0 | E22: 0
A23: Billed Msg MOU Rev by CLLI by EMR Jurisdiction | B23: Message MOU Revenue by CLLI Report | C23: 0 | D23: 0 | E23: 0
A24: CLNT ly_invoice_balances_by_jur_cic | B24: Invoice Balance Report | C24: 0 | D24: 0 | E24: 0
A25: CLNT nt_ckt_billed_live_disco_v2 | B25: Facility Circuit Charges Billed Disconnected | C25: 0 | D25: 0 | E25: 0
A26: Count of Invoices not zero Range | B26: Number Of Invoices | C26: 21B_ | D26: 0 | E26: 0
A27: Count Of Invoices not zero Range | B27: Number Of Invoices | C27: 21B_ | D27: 0 | E27: 0
A28: count_of_invoices_not_zero_range | B28: Number Of Invoices | C28: 21B_ | D28: 0 | E28: 0
A29: Deletions Under 5 Report | B29: Deletions Under 5 Report | C29: 0 | D29: 0 | E29: 0
A30: Deletions Under Report | B30: Deletions Under Report | C30: 0 | D30: 0 | E30: 0
A31: Detailed BAN Error Report | B31: Detailed BAN Error Report | C31: 4F_ | D31: 0 | E31: 0
A32: Detailed BAN Error Report - with extra research | B32: Detailed BAN Error Report | C32: 4F_ | D32: 0 | E32: 0
A33: Detailed CLLI Error Report | B33: Detailed CLLI Error Report | C33: 4H_ | D33: 0 | E33: 0
A34: Detailed CLLI Error Report - with extra research | B34: Detailed CLLI Error Report | C34: 4H_ | D34: 0 | E34: 0
A35: Duplicate File Processing Report | B35: Duplicate File Processing Report | C35: 5A_ | D35: 0 | E35: 0
A36: Exception Analysis Report | B36: Exception Analysis Report | C36: 4K_ | D36: 0 | E36: 0
A37: FA BAN Trending Report | B37: Facility BANS Trending Report | C37: 0 | D37: 0 | E37: 0
A38: FA Charges Summary | B38: FA Charges Summary | C38: 0 | D38: 0 | E38: 0
A39: FA Circuit Charges by CIC by CLLI | B39: FA Circuit Charges by CIC by CLLI | C39: 0 | D39: 0 | E39: 0
A40: Facility BANS Trending Report | B40: Facility BANS Trending Report | C40: 12B_ | D40: 12D_ | E40: 12N_
...

Sheet MIEAC
A1: Before Renaming | B1: After Renaming | C1: Code 1 | D1: Code 2 | E1: Code 3
A2: Accounting Detailed Report | B2: Accounting Detailed Report | C2: 0 | D2: 0 | E2: 0
A3: Accounting Report | B3: Accounting Report | C3: 0 | D3: 0 | E3: 0
A4: Adjustment & OCC Report | B4: Adjustment & OCC Report | C4: 12Q_ | D4: 0 | E4: 0
A5: Adjustment GL Trans by BAN Report | B5: Adjustment Report | C5: 12O_ | D5: 0 | E5: 0
A6: Adjustment GL Trans by BAN Report - New | B6: Adjustment Report | C6: 12O_ | D6: 0 | E6: 0
A7: Adjustments GL Trans by BAN Report | B7: Adjustment Report | C7: 12O_ | D7: 0 | E7: 0
A8: Adjustments Not Posted Report | B8: Adjustments Not Posted Report | C8: 9F_ | D8: 0 | E8: 0
A9: Aged Trial Balance for Export | B9: Aged Trial Balance for Export Report | C9: 0 | D9: 0 | E9: 0
A10: Aged Trial Balance for Export - New | B10: Aged Trial Balance for Export Report | C10: 0 | D10: 0 | E10: 0
A11: Aged Trial Balance_for export | B11: Aged Trial Balance for Export Report | C11: 0 | D11: 0 | E11: 0
A12: Aged trial Balance | B12: Aged trial Balance Report | C12: 13B_ | D12: 0 | E12: 0
A13: Aged Trial Balance - New | B13: Aged trial Balance Report | C13: 13B_ | D13: 0 | E13: 0
A14: AUR History Stats | B14: AUR History Stats Report | C14: 4A_ | D14: 0 | E14: 0
A15: AUR History Stats Report | B15: AUR History Stats Report | C15: 4A_ | D15: 0 | E15: 0
A16: BAN List with Active Status and LPC Option | B16: BAN List with Active Status and LPC Option | C16: 0 | D16: 0 | E16: 0
A17: Bill By Period Report | B17: Bill By Period Report | C17: 0 | D17: 0 | E17: 0
A18: Bill Completion Check Report | B18: Bill Completion Check Report | C18: 12A_ | D18: 0 | E18: 0
A19: Billed by Period | B19: Bill By Period Report | C19: 0 | D19: 0 | E19: 0
A20: Billed by Period Report | B20: Bill By Period Report | C20: 0 | D20: 0 | E20: 0
A21: Billed by Period Report - New | B21: Bill By Period Report | C21: 0 | D21: 0 | E21: 0
A22: Billed Msg MOU Rev by BAN by EMR Jurisdiction | B22: Message MOU Revenue by BAN Report | C22: 13_ | D22: 0 | E22: 0
A23: Billed Msg MOU Rev by CLLI by EMR Jurisdiction | B23: Message MOU Revenue by CLLI Report | C23: 0 | D23: 0 | E23: 0
A24: CLNT ly_invoice_balances_by_jur_cic | B24: Invoice Balance Report | C24: 0 | D24: 0 | E24: 0
A25: CLNT nt_ckt_billed_live_disco_v2 | B25: Facility Circuit Charges Billed Disconnected | C25: 0 | D25: 0 | E25: 0
A26: Count of Invoices not zero Range | B26: Number Of Invoices | C26: 21B_ | D26: 0 | E26: 0
A27: Count Of Invoices not zero Range | B27: Number Of Invoices | C27: 21B_ | D27: 0 | E27: 0
A28: count_of_invoices_not_zero_range | B28: Number Of Invoices | C28: 21B_ | D28: 0 | E28: 0
A29: Deletions Under 5 Report | B29: Deletions Under 5 Report | C29: 0 | D29: 0 | E29: 0
A30: Deletions Under Report | B30: Deletions Under Report | C30: 0 | D30: 0 | E30: 0
A31: Detailed BAN Error Report | B31: Detailed BAN Error Report | C31: 4F_ | D31: 0 | E31: 0
A32: Detailed BAN Error Report - with extra research | B32: Detailed BAN Error Report | C32: 4F_ | D32: 0 | E32: 0
A33: Detailed CLLI Error Report | B33: Detailed CLLI Error Report | C33: 4H_ | D33: 0 | E33: 0
A34: Detailed CLLI Error Report - with extra research | B34: Detailed CLLI Error Report | C34: 4H_ | D34: 0 | E34: 0
A35: Duplicate File Processing Report | B35: Duplicate File Processing Report | C35: 5A_ | D35: 0 | E35: 0
A36: Exception Analysis Report | B36: Exception Analysis Report | C36: 4K_ | D36: 0 | E36: 0
A37: FA BAN Trending Report | B37: Facility BANS Trending Report | C37: 0 | D37: 0 | E37: 0
A38: FA Charges Summary | B38: FA Charges Summary | C38: 0 | D38: 0 | E38: 0
A39: FA Circuit Charges by CIC by CLLI | B39: FA Circuit Charges by CIC by CLLI | C39: 0 | D39: 0 | E39: 0
A40: Facility BANS Trending Report | B40: Facility BANS Trending Report | C40: 12B_ | D40: 12D_ | E40: 12N_
...

Sheet Selectronics
A1: Before Renaming | B1: After Renaming | C1: Code 1 | D1: Code 2 | E1: Code 3
A2: Accounting Detailed Report | B2: Accounting Detailed Report | C2: 0 | D2: 0 | E2: 0
A3: Accounting Report | B3: Accounting Report | C3: 0 | D3: 0 | E3: 0
A4: Adjustment & OCC Report | B4: Adjustment & OCC Report | C4: 12Q_ | D4: 0 | E4: 0
A5: Adjustment GL Trans by BAN Report | B5: Adjustment Report | C5: 12O_ | D5: 0 | E5: 0
A6: Adjustment GL Trans by BAN Report - New | B6: Adjustment Report | C6: 12O_ | D6: 0 | E6: 0
A7: Adjustments GL Trans by BAN Report | B7: Adjustment Report | C7: 12O_ | D7: 0 | E7: 0
A8: Adjustments Not Posted Report | B8: Adjustments Not Posted Report | C8: 9F_ | D8: 0 | E8: 0
A9: Aged Trial Balance for Export | B9: Aged Trial Balance for Export Report | C9: 0 | D9: 0 | E9: 0
A10: Aged Trial Balance for Export - New | B10: Aged Trial Balance for Export Report | C10: 0 | D10: 0 | E10: 0
A11: Aged Trial Balance_for export | B11: Aged Trial Balance for Export Report | C11: 0 | D11: 0 | E11: 0
A12: Aged trial Balance | B12: Aged trial Balance Report | C12: 0 | D12: 0 | E12: 0
A13: Aged Trial Balance - New | B13: Aged trial Balance Report | C13: 0 | D13: 0 | E13: 0
A14: AUR History Stats | B14: AUR History Stats Report | C14: 4A_ | D14: 0 | E14: 0
A15: AUR History Stats Report | B15: AUR History Stats Report | C15: 4A_ | D15: 0 | E15: 0
A16: BAN List with Active Status and LPC Option | B16: BAN List with Active Status and LPC Option | C16: 0 | D16: 0 | E16: 0
A17: Bill By Period Report | B17: Bill By Period Report | C17: 0 | D17: 0 | E17: 0
A18: Bill Completion Check Report | B18: Bill Completion Check Report | C18: 12A_ | D18: 0 | E18: 0
A19: Billed by Period | B19: Bill By Period Report | C19: 0 | D19: 0 | E19: 0
A20: Billed by Period Report | B20: Bill By Period Report | C20: 0 | D20: 0 | E20: 0
A21: Billed by Period Report - New | B21: Bill By Period Report | C21: 0 | D21: 0 | E21: 0
A22: Billed Msg MOU Rev by BAN by EMR Jurisdiction | B22: Message MOU Revenue by BAN Report | C22: 0 | D22: 0 | E22: 0
A23: Billed Msg MOU Rev by CLLI by EMR Jurisdiction | B23: Message MOU Revenue by CLLI Report | C23: 0 | D23: 0 | E23: 0
A24: CLNT ly_invoice_balances_by_jur_cic | B24: Invoice Balance Report | C24: 0 | D24: 0 | E24: 0
A25: CLNT nt_ckt_billed_live_disco_v2 | B25: Facility Circuit Charges Billed Disconnected | C25: 0 | D25: 0 | E25: 0
A26: Count of Invoices not zero Range | B26: Number Of Invoices | C26: 21B_ | D26: 0 | E26: 0
A27: Count Of Invoices not zero Range | B27: Number Of Invoices | C27: 21B_ | D27: 0 | E27: 0
A28: count_of_invoices_not_zero_range | B28: Number Of Invoices | C28: 21B_ | D28: 0 | E28: 0
A29: Deletions Under 5 Report | B29: Deletions Under 5 Report | C29: 0 | D29: 0 | E29: 0
A30: Deletions Under Report | B30: Deletions Under Report | C30: 0 | D30: 0 | E30: 0
A31: Detailed BAN Error Report | B31: Detailed BAN Error Report | C31: 4F_ | D31: 0 | E31: 0
A32: Detailed BAN Error Report - with extra research | B32: Detailed BAN Error Report | C32: 4F_ | D32: 0 | E32: 0
A33: Detailed CLLI Error Report | B33: Detailed CLLI Error Report | C33: 4H_ | D33: 0 | E33: 0
A34: Detailed CLLI Error Report - with extra research | B34: Detailed CLLI Error Report | C34: 4H_ | D34: 0 | E34: 0
A35: Duplicate File Processing Report | B35: Duplicate File Processing Report | C35: 5A_ | D35: 0 | E35: 0
A36: Exception Analysis Report | B36: Exception Analysis Report | C36: 4K_ | D36: 0 | E36: 0
A37: FA BAN Trending Report | B37: Facility BANS Trending Report | C37: 0 | D37: 0 | E37: 0
A38: FA Charges Summary | B38: FA Charges Summary | C38: 0 | D38: 0 | E38: 0
A39: FA Circuit Charges by CIC by CLLI | B39: FA Circuit Charges by CIC by CLLI | C39: 0 | D39: 0 | E39: 0
A40: Facility BANS Trending Report | B40: Facility BANS Trending Report | C40: 12D_ | D40: 12N_ | E40: 0
...

Sheet Sprint
A1: ='Specific Names Main'!A1 -> Before Renaming | B1: ='Specific Names Main'!B1 -> After Renaming | C1: ='Specific Names Main'!C1 -> Code 1 | D1: ='Specific Names Main'!D1 -> Code 2 | E1: ='Specific Names Main'!E1 -> Code 3
A2: ='Specific Names Main'!A2 -> Accounting Detailed Report | B2: ='Specific Names Main'!B2 -> Accounting Detailed Report | C2: ='Specific Names Main'!C2 -> 0 | D2: ='Specific Names Main'!D2 -> 0 | E2: ='Specific Names Main'!E2 -> 0
A3: ='Specific Names Main'!A3 -> Accounting Report | B3: ='Specific Names Main'!B3 -> Accounting Report | C3: ='Specific Names Main'!C3 -> 0 | D3: ='Specific Names Main'!D3 -> 0 | E3: ='Specific Names Main'!E3 -> 0
A4: ='Specific Names Main'!A4 -> Adjustment & OCC Report | B4: ='Specific Names Main'!B4 -> Adjustment & OCC Report | C4: ='Specific Names Main'!C4 -> 12Q_ | D4: ='Specific Names Main'!D4 -> 0 | E4: ='Specific Names Main'!E4 -> 0
A5: ='Specific Names Main'!A5 -> Adjustment GL Trans by BAN Report | B5: ='Specific Names Main'!B5 -> Adjustment Report | C5: ='Specific Names Main'!C5 -> 12O_ | D5: ='Specific Names Main'!D5 -> 0 | E5: ='Specific Names Main'!E5 -> 0
A6: ='Specific Names Main'!A6 -> Adjustment GL Trans by BAN Report - New | B6: ='Specific Names Main'!B6 -> Adjustment Report | C6: ='Specific Names Main'!C6 -> 12O_ | D6: ='Specific Names Main'!D6 -> 0 | E6: ='Specific Names Main'!E6 -> 0
A7: ='Specific Names Main'!A7 -> Adjustments GL Trans by BAN Report | B7: ='Specific Names Main'!B7 -> Adjustment Report | C7: ='Specific Names Main'!C7 -> 12O_ | D7: ='Specific Names Main'!D7 -> 0 | E7: ='Specific Names Main'!E7 -> 0
A8: ='Specific Names Main'!A8 -> Adjustments Not Posted Report | B8: ='Specific Names Main'!B8 -> Adjustments Not Posted Report | C8: ='Specific Names Main'!C8 -> 9F_ | D8: ='Specific Names Main'!D8 -> 0 | E8: ='Specific Names Main'!E8 -> 0
A9: ='Specific Names Main'!A9 -> Aged Trial Balance for Export | B9: ='Specific Names Main'!B9 -> Aged Trial Balance for Export Report | C9: ='Specific Names Main'!C9 -> 0 | D9: ='Specific Names Main'!D9 -> 0 | E9: ='Specific Names Main'!E9 -> 0
A10: ='Specific Names Main'!A10 -> Aged Trial Balance for Export - New | B10: ='Specific Names Main'!B10 -> Aged Trial Balance for Export Report | C10: ='Specific Names Main'!C10 -> 0 | D10: ='Specific Names Main'!D10 -> 0 | E10: ='Specific Names Main'!E10 -> 0
A11: ='Specific Names Main'!A11 -> Aged Trial Balance_for export | B11: ='Specific Names Main'!B11 -> Aged Trial Balance for Export Report | C11: ='Specific Names Main'!C11 -> 0 | D11: ='Specific Names Main'!D11 -> 0 | E11: ='Specific Names Main'!E11 -> 0
A12: ='Specific Names Main'!A12 -> Aged trial Balance | B12: ='Specific Names Main'!B12 -> Aged trial Balance Report | C12: ='Specific Names Main'!C12 -> 0 | D12: ='Specific Names Main'!D12 -> 0 | E12: ='Specific Names Main'!E12 -> 0
... A500: ='Specific Names Main'!A500 -> 0 | B500: ='Specific Names Main'!B500 -> 0 | C500: ='Specific Names Main'!C500 -> 0 | D500: ='Specific Names Main'!D500 -> 0 | E500: ='Specific Names Main'!E500 -> 0

Sheet BendTel
A1: BeforeRenaming | B1: AfterRenaming | C1: Code1 | D1: Code2 | E1: Code3
A2: Accounting Detailed Report | B2: Accounting Detailed Report
A3: Accounting Report | B3: Accounting Report
A4: Adjustment & OCC Report | B4: Adjustment & OCC Report | C4: 12Q_
A5: Adjustment GL Trans by BAN Report | B5: Adjustment Report | C5: 12O_
A6: Adjustment GL Trans by BAN Report - New | B6: Adjustment Report | C6: 12O_
A7: Adjustments GL Trans by BAN Report | B7: Adjustment Report | C7: 12O_
A8: Adjustments Not Posted Report | B8: Adjustments Not Posted Report | C8: 9F_
A9: Aged Trial Balance for Export | B9: Aged Trial Balance for Export Report
A10: Aged Trial Balance for Export - New | B10: Aged Trial Balance for Export Report
A11: Aged Trial Balance_for export | B11: Aged Trial Balance for Export Report
A12: Aged trial Balance | B12: Aged trial Balance Report
A13: Aged Trial Balance - New | B13: Aged trial Balance Report
A14: AUR History Stats | B14: AUR History Stats Report | C14: 4A_
A15: AUR History Stats Report | B15: AUR History Stats Report | C15: 4A_
A16: BAN List with Active Status and LPC Option | B16: BAN List with Active Status and LPC Option
A17: Bill By Period Report | B17: Bill By Period Report
A18: Bill Completion Check Report | B18: Bill Completion Check Report | C18: 12A_
A19: Billed by Period | B19: Bill By Period Report
A20: Billed by Period Report | B20: Bill By Period Report
A21: Billed by Period Report - New | B21: Bill By Period Report
A22: Billed Msg MOU Rev by BAN by EMR Jurisdiction | B22: Message MOU Revenue by BAN Report
A23: Billed Msg MOU Rev by CLLI by EMR Jurisdiction | B23: Message MOU Revenue by CLLI Report
A24: CLNT ly_invoice_balances_by_jur_cic | B24: Invoice Balance Report
A25: CLNT nt_ckt_billed_live_disco_v2 | B25: Facility Circuit Charges Billed Disconnected
A26: Count of Invoices not zero Range | B26: Number Of Invoices | C26: 21B_
A27: Count Of Invoices not zero Range | B27: Number Of Invoices | C27: 21B_
A28: count_of_invoices_not_zero_range | B28: Number Of Invoices | C28: 21B_
A29: Deletions Under 5 Report | B29: Deletions Under 5 Report
A30: Deletions Under Report | B30: Deletions Under Report
A31: Detailed BAN Error Report | B31: Detailed BAN Error Report | C31: 4F_
A32: Detailed BAN Error Report - with extra research | B32: Detailed BAN Error Report | C32: 4F_
A33: Detailed CLLI Error Report | B33: Detailed CLLI Error Report | C33: 4H_
A34: Detailed CLLI Error Report - with extra research | B34: Detailed CLLI Error Report | C34: 4H_
A35: Duplicate File Processing Report | B35: Duplicate File Processing Report | C35: 5A_
A36: Exception Analysis Report | B36: Exception Analysis Report | C36: 4K_
A37: FA BAN Trending Report | B37: Facility BANS Trending Report
A38: FA Charges Summary | B38: FA Charges Summary
A39: FA Circuit Charges by CIC by CLLI | B39: FA Circuit Charges by CIC by CLLI
A40: Facility BANS Trending Report | B40: Facility BANS Trending Report | C40: 12B_ | D40: 12D_ | E40: 12N_
...

Sheet GCI
A1: Before Renaming | B1: After Renaming | C1: Code 1 | D1: Code 2 | E1: Code 3
A2: Accounting Detailed Report | B2: Accounting Detailed Report | C2: 0 | D2: 0 | E2: 0
A3: Accounting Report | B3: Accounting Report | C3: 0 | D3: 0 | E3: 0
A4: Adjustment & OCC Report | B4: Adjustment & OCC Report | C4: 12Q_ | D4: 0 | E4: 0
A5: Adjustment GL Trans by BAN Report | B5: Adjustment Report | C5: 12O_ | D5: 0 | E5: 0
A6: Adjustment GL Trans by BAN Report - New | B6: Adjustment Report | C6: 12O_ | D6: 0 | E6: 0
A7: Adjustments GL Trans by BAN Report | B7: Adjustment Report | C7: 12O_ | D7: 0 | E7: 0
A8: Adjustments Not Posted Report | B8: Adjustments Not Posted Report | C8: 9F_ | D8: 0 | E8: 0
A9: Aged Trial Balance for Export | B9: Aged Trial Balance for Export Report | C9: 0 | D9: 0 | E9: 0
A10: Aged Trial Balance for Export - New | B10: Aged Trial Balance for Export Report | C10: 0 | D10: 0 | E10: 0
A11: Aged Trial Balance_for export | B11: Aged Trial Balance for Export Report | C11: 0 | D11: 0 | E11: 0
A12: Aged trial Balance | B12: Aged trial Balance Report | C12: 0 | D12: 0 | E12: 0
A13: Aged Trial Balance - New | B13: Aged trial Balance Report | C13: 0 | D13: 0 | E13: 0
A14: AUR History Stats | B14: AUR History Stats Report | C14: 4A_ | D14: 0 | E14: 0
A15: AUR History Stats Report | B15: AUR History Stats Report | C15: 4A_ | D15: 0 | E15: 0
A16: BAN List with Active Status and LPC Option | B16: BAN List with Active Status and LPC Option | C16: 0 | D16: 0 | E16: 0
A17: Bill By Period Report | B17: Bill By Period Report | C17: 0 | D17: 0 | E17: 0
A18: Bill Completion Check Report | B18: Bill Completion Check Report | C18: 12A_ | D18: 0 | E18: 0
A19: Billed by Period | B19: Bill By Period Report | C19: 0 | D19: 0 | E19: 0
A20: Billed by Period Report | B20: Bill By Period Report | C20: 0 | D20: 0 | E20: 0
A21: Billed by Period Report - New | B21: Bill By Period Report | C21: 0 | D21: 0 | E21: 0
A22: Billed Msg MOU Rev by BAN by EMR Jurisdiction | B22: Message MOU Revenue by BAN Report | C22: 0 | D22: 0 | E22: 0
A23: Billed Msg MOU Rev by CLLI by EMR Jurisdiction | B23: Message MOU Revenue by CLLI Report | C23: 0 | D23: 0 | E23: 0
A24: CLNT ly_invoice_balances_by_jur_cic | B24: Invoice Balance Report | C24: 0 | D24: 0 | E24: 0
A25: CLNT nt_ckt_billed_live_disco_v2 | B25: Facility Circuit Charges Billed Disconnected | C25: 0 | D25: 0 | E25: 0
A26: Count of Invoices not zero Range | B26: Number Of Invoices | C26: 21B_ | D26: 0 | E26: 0
A27: Count Of Invoices not zero Range | B27: Number Of Invoices | C27: 21B_ | D27: 0 | E27: 0
A28: count_of_invoices_not_zero_range | B28: Number Of Invoices | C28: 21B_ | D28: 0 | E28: 0
A29: Deletions Under 5 Report | B29: Deletions Under 5 Report | C29: 0 | D29: 0 | E29: 0
A30: Deletions Under Report | B30: Deletions Under Report | C30: 0 | D30: 0 | E30: 0
A31: Detailed BAN Error Report | B31: Detailed BAN Error Report | C31: 4F_ | D31: 0 | E31: 0
A32: Detailed BAN Error Report - with extra research | B32: Detailed BAN Error Report | C32: 4F_ | D32: 0 | E32: 0
A33: Detailed CLLI Error Report | B33: Detailed CLLI Error Report | C33: 4H_ | D33: 0 | E33: 0
A34: Detailed CLLI Error Report - with extra research | B34: Detailed CLLI Error Report | C34: 4H_ | D34: 0 | E34: 0
A35: Duplicate File Processing Report | B35: Duplicate File Processing Report | C35: 5A_ | D35: 0 | E35: 0
A36: Exception Analysis Report | B36: Exception Analysis Report | C36: 4K_ | D36: 0 | E36: 0
A37: FA BAN Trending Report | B37: Facility BANS Trending Report | C37: 0 | D37: 0 | E37: 0
A38: FA Charges Summary | B38: FA Charges Summary | C38: 0 | D38: 0 | E38: 0
A39: FA Circuit Charges by CIC by CLLI | B39: FA Circuit Charges by CIC by CLLI | C39: 0 | D39: 0 | E39: 0
A40: Facility BANS Trending Report | B40: Facility BANS Trending Report | C40: 12B_ | D40: 12D_ | E40: 12N_
...

Sheet Prefix
A1: Client | B1: prefix | C1: bill date
A2: Selectronics | B2: 0069_VT | C2: 01
A3: American_Broadband356D_MI | B3: 356D_MI | C3: 25
A4: American_Broadband509B_OH | B4: 509B_OH | C4: 20
A5: American_Broadband590G_IN | B5: 590G_IN | C5: 25
A6: BendTel | B6: 9627_OR | C6: 22
A7: MIEAC | B7: MIEAC | C7: 01
A8: ONVOY | B8: ONVOY | C8: 01
A9: Peerless_Network | B9: Peerless | C9: 05
A10: Neutral_TandemFA | B10: Combined_IQNT | C10: 01
A11: Neutral_TandemSW | B11: Combined | C11: 01
A12: Neutral_TandemSWO | B12: Combined_OSA | C12: 05
... A18: GCIFA | B18: GCI_FA | C18: 10
A19: Sprint

Sheet mps_database
A1: MPS Location | B1: Report Name | C1: File Location | D1: Coordinates
A2: 1 | B2: Verify Prior Period Post Date | D2: D17
A3: 1A | B3: Last date data was received. | D3: D18
A4: 1B | B4: Run Usage Balancing Report. Verify AUR = MOU | D4: D19
A5: 1C | B5: Client Final Approval of Usage Files | D5: D20
A6: 2 | B6: Verify From and To Cycle Dates | D6: D21
A7: 2A | B7: From cycle date: | D7: D22
A8: 2B | B8: To cycle date: | D8: D23
A9: 2C | B9: Bill Date | D9: D24
A10: 4A | B10: AUR History Stats Report | C10: K:\Client\MIEAC\Reports\2021\06_2021\MIEAC_060121_4A_AUR History Report.xls | D10: D32
A11: 4B | B11: Verify Bill Count | D11: D33
A12: 4C | B12: File Count: | D12: D34
A13: 4D | B13: Record Count: | D13: D35
A14: 4E | B14: Verify Count: | D14: D36
A15: 4F | B15: BAN Error Report | C15: K:\Client\MIEAC\Reports\2021\06_2021\MIEAC_060121_4F_Detailed BAN Error Report.xlsx | D15: D37
A16: 4G | B16: Set Up New BANs | D16: D38
A17: 4H | B17: CLLI Error Report | C17: K:\Client\MIEAC\Reports\2021\06_2021\MIEAC_060121_4H_No CLLI Report.xls | D17: D39
A18: 4I | B18: Set Up New CLLIs | D18: D40
A19: 4J | B19: CLLI Verification | D19: D41
A20: 4K | B20: Exception Analysis Report | C20: K:\Client\MIEAC\Reports\2021\06_2021\MIEAC_060121_4K_Exception Analysis Report.pdf | D20: D42
A21: 4L | B21: MOU Entries Error Report | C21: K:\Client\MIEAC\Reports\2021\06_2021\MIEAC_060121_4L_MOU Entries Error Report.pdf | D21: D43
A22: 4M | B22: NON MOU Entries Error Report | D22: D44
A23: 4N | B23: Process Fix Files | D23: D45
A24: 4O | B24: Install New Circuits | D24: D46
A25: 5 | B25: Analyze Files for Duplicate Processing and Non Processed Files | D25: D47
A26: 5A | B26: Duplicate File Processing Report | C26: K:\Client\MIEAC\Reports\2021\06_2021\MIEAC_060121_5A_Duplicate File Processing Report.pdf | D26: D48
A27: 5B | B27: Error Files Duplicate Report | D27: D49
A28: 5C | B28: Usage Verify by Size Report | C28: K:\Client\MIEAC\Reports\2021\06_2021\MIEAC_060121_5C_Usage Verify by Size Report.pdf | D28: D50
A29: 5D | B29: Usage By Day Report (NOTIFY CLIENT OF MISSING USAGE) | C29: K:\Client\MIEAC\Reports\2021\06_2021\MIEAC_060121_5D_Usage By Day Report.xlsx | D29: D51
A30: 5E-3MONTHS | B30: Usage By Day Report - 3 Month Period | C30: K:\Client\MIEAC\Reports\2021\06_2021\MIEAC_060121_5E-3MONTHS_Usage By Day Report.xlsx | D30: D52
A31: 5F | B31: Copy period error files to the following month Q folder | D31: D53
A32: 5G | B32: Zip files, analyze non-zipped files | D32: D54
A33: 5H | B33: Renewals, Changes, and/or New Rate | D33: D55
A34: 5I | B34: Disconnects | D34: D56
A35: 5J | B35: Preliminary Balancing Report | D35: D57
A36: 5k | B36: Duplicate File Processing Report by Name | D36: D58
A37: 5L | B37: Update Rate Change Calculator | D37: D59
A38: 5M | B38: Usage Variance Report | D38: D60
A39: 6 | B39: Usage Balancing Report | C39: K:\Client\MIEAC\Reports\2021\06_2021\MIEAC_060121_6_Company BAN Total Report.pdf | D39: D61
A40: 7 | B40: Enter MOU Exceptions | D40: D62
...

Sheet Specific Names draft
A1: Name | B1: Pattern | C1: Array
A2: Payment Report | B2: <prefix>_<mm>10<yy>_<ar>Payment Report | C2: 8
A3: Factor Change Audit Report | B3: <prefix>_<mm>10<yy>_<ar>Factor Change Audit Report | C3: 10
A4: SOC Change Audit Report | B4: <prefix>_<mm>10<yy>_<ar>SOC Change Audit Report | C4: 11
A5: Factor Check Report with PVU | B5: <prefix>_<mm>10<yy>_<ar>Factor Check Report with PVU | C5: 10A
A6: Usage Balancing - Company Totals with Full Detail | B6: <prefix>_<mm>10<yy>_<ar>FGA Usage Balance Details | C6: 11B
A7: Bill Completion Check Report | B7: <prefix>_<mm>10<yy>_<ar>Bill Completion Check Report | C7: 12A
A8: Switched BANS Trending Report | B8: <prefix>_<mm>10<yy>_<ar>Switched BANS Trending Report | C8: 12B
A9: Adjustment GL Trans by BAN Report | B9: <prefix>_<mm>10<yy>_<ar>Adjustments Report | C9: 12O
A10: OC&C GL Trans by BAN Report | B10: <prefix>_<mm>10<yy>_<ar>OCCs Report | C10: 12P
A11: count_of_invoices_not_zero_range | B11: <prefix>_<mm>10<yy>_<ar>Invoice Count | C11: 21B
A12: AUR History Stats Report | B12: <prefix>_<mm>10<yy>_<ar>AUR History Stats Report | C12: 4A
A13: Detailed BAN Error Report - with extra research | B13: <prefix>_<mm>10<yy>_<ar>Detailed BAN Error Report | C13: 4F
A14: Detailed CLLI Error Report | B14: <prefix>_<mm>10<yy>_<ar>Detailed CLLI Error Report | C14: 4H
A15: Exception Analysis Report | B15: <prefix>_<mm>10<yy>_<ar>Exception Analysis Report | C15: 4K
A16: MOU Entries Error Report | B16: <prefix>_<mm>10<yy>_<ar>MOU Entries Error Report | C16: 4L
... A21: Adjustments Not Posted Report | B21: <prefix>_<mm>10<yy>_<ar>Adjustments Not Posted Report | C21: 9F
A22: Aged Trial Balance for Export | B22: <prefix>_<mm>10<yy>_<ar>Aged Trial Balance for Export Report
A23: Billed by Period | B23: <prefix>_<mm>10<yy>_<ar>Billed by Period Report
A24: Billed Msg MOU Rev by BAN by EMR Jurisdiction | B24: <prefix>_<mm>10<yy>_<ar>Message MOU Revenue by BAN Report
A25: Billed Msg MOU Rev by CLLI by EMR Jurisdiction | B25: <prefix>_<mm>10<yy>_<ar>Message MOU Revenue by CLLI Report
A26: Minutes and revenue billed by rate element | B26: <prefix>_<mm>10<yy>_<ar>Minutes and Revenue Billed By Rate Element Report
A27: SW Usage Charges Summary | B27: <prefix>_<mm>10<yy>_<ar>SW Usage Charges Summary Report
A28: Transaction Summary - bills only | B28: <prefix>_<mm>10<yy>_<ar>Transaction Summary Report
A29: Payment Report | B29: ="<prefix>_<mm>05<yy>_<ar>"&A29 -> <prefix>_<mm>05<yy>_<ar>Payment Report | C29: 8
A30: Factor Change Audit Report | B30: ="<prefix>_<mm>05<yy>_<ar>"&A30 -> <prefix>_<mm>05<yy>_<ar>Factor Change Audit Report | C30: 10
A31: SOC Change Audit Report | B31: ="<prefix>_<mm>05<yy>_<ar>"&A31 -> <prefix>_<mm>05<yy>_<ar>SOC Change Audit Report | C31: 11
A32: Factor Check Report with PVU | B32: <prefix>_<mm>05<yy>_<ar>Factor Check Report | C32: 10A
A33: Bill Completion Check Report | B33: ="<prefix>_<mm>05<yy>_<ar>"&A33 -> <prefix>_<mm>05<yy>_<ar>Bill Completion Check Report | C33: 12A
A34: Switched BANS Trending Report | B34: <prefix>_<mm>05<yy>_<ar>Switched BANS Trending Report | C34: 12B
A35: Adjustment GL Trans by BAN Report | B35: <prefix>_<mm>05<yy>_<ar>Adjustments Report | C35: 12O
A36: OC&C GL Trans by BAN Report | B36: <prefix>_<mm>05<yy>_<ar>OCCs Report | C36: 12P
A37: count_of_invoices_not_zero_range | B37: <prefix>_<mm>05<yy>_<ar>Invoice Count | C37: 21B
A38: AUR History Stats Report | B38: <prefix>_<mm>05<yy>_<ar>AUR History Stats Report | C38: 4A
A39: Detailed BAN Error Report - with extra research | B39: <prefix>_<mm>05<yy>_<ar>Detailed BAN Error Report | C39: 4F
A40: Detailed CLLI Error Report | B40: <prefix>_<mm>05<yy>_<ar>Detailed CLLI Error Report | C40: 4H
A41: Exception Analysis Report | B41: <prefix>_<mm>05<yy>_<ar>Exception Analysis Report | C41: 4K
A42: MOU Entries Error Report | B42: <prefix>_<mm>05<yy>_<ar>MOU Entries Error Report | C42: 4L
A43: Duplicate File Processing Report | B43: <prefix>_<mm>05<yy>_<ar>Duplicate File Processing Report | C43: 5A
A44: Usage Verify by Size Report | B44: <prefix>_<mm>05<yy>_<ar>Usage Verify by Size Report | C44: 5C
...

Sheet Patterns
A1: AMBB | B1: <prefix>_<mm>_25_<yyyy>_<ar>Revenue
A2: Bendtel | B2: <prefix>_<mm>_22_<yy>_<ar>SOC Rate Comparison between companies
A3: GCI SW | B3: <prefix>_<mm><cy><yy>_<ar>Switched Billing Account - Factor Report
A4: MIEAC | B4: <prefix>_<mm>01<yy>_<ar>Summary of Adjustments Report
A5: MTA FA | B5: <prefix>_<mm>10<yy>_<ar>Factor Audit Report
A6: MTA RC | B6: <prefix>_<mm>05<yy>_<ar>Payment Report
A7: MTA SW | B7: <prefix>_<mm>10<yy>_<ar>Payment Report
A8: NT FA | B8: Combined_<prefix>_<mm><cy><yy>_<ar>Payment Report
A9: NT SW | B9: Combined_<prefix>_<mm><cy><yy>_<ar>Payments
B10: Combined_<mm><yy>_<ar>Bill Completion Check Report
A11: Onvoy | B11: <prefix>_<mm>01<yy>_<ar>Payment Report
A12: Perless | B12: <prefix>_<mm>-05-<yy>_<ar>Usage Verify by Size Report
A13: Selectronics | B13: <prefix>_<mm>01<yy>_<ar>Payment Report
A14: Sprint | B14: <prefix>_<mm>20<yyyy>_<ar>Detailed BAN Error Report

Sheet Draft
A1: Name | B1: Pattern | C1: Array
A2: Payment Report | B2: ="<prefix>_<mm>10<yy>_<ar>"&A2 -> <prefix>_<mm>10<yy>_<ar>Payment Report | C2: 8
A3: Factor Change Audit Report | B3: ="<prefix>_<mm>10<yy>_<ar>"&A3 -> <prefix>_<mm>10<yy>_<ar>Factor Change Audit Report | C3: 10
A4: SOC Change Audit Report | B4: ="<prefix>_<mm>10<yy>_<ar>"&A4 -> <prefix>_<mm>10<yy>_<ar>SOC Change Audit Report | C4: 11
A5: Factor Check Report with PVU | B5: ="<prefix>_<mm>10<yy>_<ar>"&A5 -> <prefix>_<mm>10<yy>_<ar>Factor Check Report with PVU | C5: 10A
A6: Usage Balancing - Company Totals with Full Detail | B6: <prefix>_<mm>10<yy>_<ar>FGA Usage Balance Details | C6: 11B
A7: Bill Completion Check Report | B7: ="<prefix>_<mm>10<yy>_<ar>"&A7 -> <prefix>_<mm>10<yy>_<ar>Bill Completion Check Report | C7: 12A
A8: Switched BANS Trending Report | B8: ="<prefix>_<mm>10<yy>_<ar>"&A8 -> <prefix>_<mm>10<yy>_<ar>Switched BANS Trending Report | C8: 12B
A9: Adjustment GL Trans by BAN Report | B9: <prefix>_<mm>10<yy>_<ar>Adjustments Report | C9: 12O
A10: OC&C GL Trans by BAN Report | B10: <prefix>_<mm>10<yy>_<ar>OCCs Report | C10: 12P
A11: count_of_invoices_not_zero_range | B11: <prefix>_<mm>10<yy>_<ar>Invoice Count | C11: 21B
A12: AUR History Stats Report | B12: ="<prefix>_<mm>10<yy>_<ar>"&A12 -> <prefix>_<mm>10<yy>_<ar>AUR History Stats Report | C12: 4A
A13: Detailed BAN Error Report - with extra research | B13: <prefix>_<mm>10<yy>_<ar>Detailed BAN Error Report | C13: 4F
A14: Detailed CLLI Error Report | B14: ="<prefix>_<mm>10<yy>_<ar>"&A14 -> <prefix>_<mm>10<yy>_<ar>Detailed CLLI Error Report | C14: 4H
A15: Exception Analysis Report | B15: ="<prefix>_<mm>10<yy>_<ar>"&A15 -> <prefix>_<mm>10<yy>_<ar>Exception Analysis Report | C15: 4K
A16: MOU Entries Error Report | B16: ="<prefix>_<mm>10<yy>_<ar>"&A16 -> <prefix>_<mm>10<yy>_<ar>MOU Entries Error Report | C16: 4L
A17: Duplicate File Processing Report | B17: ="<prefix>_<mm>10<yy>_<ar>"&A17 -> <prefix>_<mm>10<yy>_<ar>Duplicate File Processing Report | C17: 5A
A18: Usage Verify by Size Report | B18: ="<prefix>_<mm>10<yy>_<ar>"&A18 -> <prefix>_<mm>10<yy>_<ar>Usage Verify by Size Report | C18: 5C
A19: Usage By Day Report | B19: ="<prefix>_<mm>10<yy>_<ar>"&A19 -> <prefix>_<mm>10<yy>_<ar>Usage By Day Report | C19: 5D,5E-3months
A20: Usage Balancing - Company, Ban Totals | B20: <prefix>_<mm>10<yy>_<ar>Usage Balancing | C20: 6,11C-Post-FGA,13
A21: Adjustments Not Posted Report | B21: ="<prefix>_<mm>10<yy>_<ar>"&A21 -> <prefix>_<mm>10<yy>_<ar>Adjustments Not Posted Report | C21: 9F
A22: Aged Trial Balance for Export | B22: <prefix>_<mm>10<yy>_<ar>Aged Trial Balance for Export Report
A23: Billed by Period | B23: <prefix>_<mm>10<yy>_<ar>Billed by Period Report
A24: Billed Msg MOU Rev by BAN by EMR Jurisdiction | B24: <prefix>_<mm>10<yy>_<ar>Message MOU Revenue by BAN Report
A25: Billed Msg MOU Rev by CLLI by EMR Jurisdiction | B25: <prefix>_<mm>10<yy>_<ar>Message MOU Revenue by CLLI Report
A26: Minutes and revenue billed by rate element | B26: <prefix>_<mm>10<yy>_<ar>Minutes and Revenue Billed By Rate Element Report
A27: SW Usage Charges Summary | B27: <prefix>_<mm>10<yy>_<ar>SW Usage Charges Summary Report
A28: Transaction Summary - bills only | B28: <prefix>_<mm>10<yy>_<ar>Transaction Summary Report
A29: Access MSG and MOU billed by CLLI,FG,CIC | B29: ="<prefix>_<mm>10<yy>_<ar>"&A29 -> <prefix>_<mm>10<yy>_<ar>Access MSG and MOU billed by CLLI,FG,CIC
A30: Adjustments Detail Report - Posted | B30: ="<prefix>_<mm>10<yy>_<ar>"&A30 -> <prefix>_<mm>10<yy>_<ar>Adjustments Detail Report - Posted
A31: Adjustments Detail Report - Unposted | B31: ="<prefix>_<mm>10<yy>_<ar>"&A31 -> <prefix>_<mm>10<yy>_<ar>Adjustments Detail Report - Unposted
A32: Aged trial Balance | B32: ="<prefix>_<mm>10<yy>_<ar>"&A32 -> <prefix>_<mm>10<yy>_<ar>Aged trial Balance
A33: Aged Trial Balance by Company | B33: ="<prefix>_<mm>10<yy>_<ar>"&A33 -> <prefix>_<mm>10<yy>_<ar>Aged Trial Balance by Company
A34: Amount billed/disputed/settled by month/carrier | B34: ="<prefix>_<mm>10<yy>_<ar>"&A34 -> <prefix>_<mm>10<yy>_<ar>Amount billed/disputed/settled by month/carrier
A35: Amount billed/disputed/settled by qtr/carrier | B35: ="<prefix>_<mm>10<yy>_<ar>"&A35 -> <prefix>_<mm>10<yy>_<ar>Amount billed/disputed/settled by qtr/carrier
A36: Amount billed-disputed-settled by month-carrier | B36: ="<prefix>_<mm>10<yy>_<ar>"&A36 -> <prefix>_<mm>10<yy>_<ar>Amount billed-disputed-settled by month-carrier
A37: Amount billed-disputed-settled by qtr-carrier | B37: ="<prefix>_<mm>10<yy>_<ar>"&A37 -> <prefix>_<mm>10<yy>_<ar>Amount billed-disputed-settled by qtr-carrier
A38: AS1000 Report | B38: ="<prefix>_<mm>10<yy>_<ar>"&A38 -> <prefix>_<mm>10<yy>_<ar>AS1000 Report
A39: AUR History Stats | B39: ="<prefix>_<mm>10<yy>_<ar>"&A39 -> <prefix>_<mm>10<yy>_<ar>AUR History Stats
A40: AUR History Stats (Seconds) | B40: ="<prefix>_<mm>10<yy>_<ar>"&A40 -> <prefix>_<mm>10<yy>_<ar>AUR History Stats (Seconds)
...

Sheet mps_database1
A1: ID | B1: MPSLocation | C1: ReportName | D1: FileLocation | E1: Coordinates
A2: 1 | B2: 1 | C2: Verify Prior Period Post Date | E2: D17
A3: 2 | B3: 1A | C3: Last date data was received. | E3: D18
A4: 3 | B4: 1B | C4: Run Usage Balancing Report. Verify AUR = MOU | E4: D19
A5: 4 | B5: 1C | C5: Client Final Approval of Usage Files | E5: D20
A6: 5 | B6: 2 | C6: Verify From and To Cycle Dates | E6: D21
A7: 6 | B7: 2A | C7: From cycle date: | E7: D22
A8: 7 | B8: 2B | C8: To cycle date: | E8: D23
A9: 8 | B9: 2C | C9: Bill Date | E9: D24
A10: 9 | B10: 4A | C10: AUR History Stats Report | E10: D32
A11: 10 | B11: 4B | C11: Verify Bill Count | E11: D33
A12: 11 | B12: 4C | C12: File Count: | E12: D34
A13: 12 | B13: 4D | C13: Record Count: | E13: D35
... A282: 281 | B282: 21BTTS | C282: Number of InvoicesTTS | E282: F228
A283: 282 | B283: 19QOSA | C283: Invoice Balances by Jur with LPCOSA
A284: 283 | B284: 19QTTS | C284: Invoice Balances by Jur with LPCTTS
